<sdf version='1.6'>
  <model name='rvc'>
    <link name='base_link'>
      <pose frame=''>0 0 0 0 -0 0</pose>
      <inertial>
        <pose frame=''>0.040385 0 0.047692 0 -0 0</pose>
        <mass>2.6</mass>
        <inertia>
          <ixx>0.0175781</ixx>
          <ixy>0</ixy>
          <ixz>-3.23077e-05</ixz>
          <iyy>0.0175827</iyy>
          <iyz>0</iyz>
          <izz>0.0327389</izz>
        </inertia>
      </inertial>
      <collision name='base_link_fixed_joint_lump__boby_collision_collision'>
        <pose frame=''>0 0 0.045 0 -0 0</pose>
        <geometry>
          <cylinder>
            <length>0.07</length>
            <radius>0.16495</radius>
          </cylinder>
        </geometry>
      </collision>
      <collision name='base_link_fixed_joint_lump__front_omniwheel_collision_1'>
        <pose frame=''>0.11 0 0.009 0 -0 0</pose>
        <geometry>
          <sphere>
            <radius>0.009</radius>
          </sphere>
        </geometry>
      </collision>
      <collision name='base_link_fixed_joint_lump__back_omniwheel_collision_2'>
        <pose frame=''>-0.11 0 0.009 0 -0 0</pose>
        <geometry>
          <sphere>
            <radius>0.008</radius>
          </sphere>
        </geometry>
      </collision>
      <collision name='base_link_fixed_joint_lump__collision_collision_3'>
        <pose frame=''>0.045 0 0.08 0 -0 0</pose>
        <geometry>
          <cylinder>
            <length>0.017</length>
            <radius>0.029</radius>
          </cylinder>
        </geometry>
      </collision>
      <visual name='base_link_fixed_joint_lump__body_visual'>
        <pose frame=''>0 0 0.045 0 -0 0</pose>
        <geometry>
          <mesh>
            <scale>1 1 1</scale>
            <uri>model://sweeper_description/meshes/RobotBody.dae</uri>
          </mesh>
        </geometry>
        <material>
          <script>
            <name>Gazebo/White</name>
            <uri>file://media/materials/scripts/gazebo.material</uri>
          </script>
        </material>
      </visual>
      <visual name='base_link_fixed_joint_lump__recevier_visual_1'>
        <pose frame=''>0.161659 0.009711 0.105 0 -0 0.06</pose>
        <geometry>
          <sphere>
            <radius>0.005</radius>
          </sphere>
        </geometry>
      </visual>
      <visual name='base_link_fixed_joint_lump__recevier_visual_2'>
        <pose frame=''>0.161659 -0.009711 0.105 0 0 -0.06</pose>
        <geometry>
          <sphere>
            <radius>0.005</radius>
          </sphere>
        </geometry>
      </visual>
      <visual name='base_link_fixed_joint_lump__recevier_visual_3'>
        <pose frame=''>0 0.16195 0.105 0 -0 1.57079</pose>
        <geometry>
          <sphere>
            <radius>0.005</radius>
          </sphere>
        </geometry>
      </visual>
      <visual name='base_link_fixed_joint_lump__recevier_visual_4'>
        <pose frame=''>0 -0.16195 0.105 0 0 -1.57079</pose>
        <geometry>
          <sphere>
            <radius>0.005</radius>
          </sphere>
        </geometry>
      </visual>
      <visual name='base_link_fixed_joint_lump__laser_visual_visual_5'>
        <pose frame=''>0.045 0 0.08 0 -0 0</pose>
        <geometry>
          <mesh>
            <scale>1 1 1</scale>
            <uri>model://sweeper_description/meshes/RobotLidar.dae</uri>
          </mesh>
        </geometry>
      </visual>
      <velocity_decay/>
      <sensor name='main_bumper' type='contact'>
        <contact>
          <collision>base_link_fixed_joint_lump__boby_collision_collision</collision>
          <topic>__default_topic__</topic>
        </contact>
        <plugin name='gazebo_ros_bumper_controller' filename='libgazebo_ros_bumper.so'>
          <selfCollide>true</selfCollide>
          <alwaysOn>true</alwaysOn>
          <updateRate>50.0</updateRate>
          <bumperTopicName>/bumper</bumperTopicName>
          <frameName>base_link</frameName>
        </plugin>
        <pose frame=''>0 0 0.045 0 -0 0</pose>
      </sensor>
      <velocity_decay/>
      <sensor name='ir_front_sensor' type='ray'>
        <visualize>1</visualize>
        <update_rate>20</update_rate>
        <ray>
          <scan>
            <horizontal>
              <samples>10</samples>
              <resolution>1</resolution>
              <min_angle>-0.0872664</min_angle>
              <max_angle>0.0872664</max_angle>
            </horizontal>
          </scan>
          <range>
            <min>0.01</min>
            <max>0.26</max>
            <resolution>0.01</resolution>
          </range>
        </ray>
        <plugin name='gazebo_ros_ir_front_controller' filename='libgazebo_ros_range.so'>
          <gaussianNoise>0.005</gaussianNoise>
          <alwaysOn>true</alwaysOn>
          <updateRate>20</updateRate>
          <topicName>/ir/front</topicName>
          <frameName>base_link</frameName>
          <radiation>ir</radiation>
          <fov>0.174532777778</fov>
        </plugin>
        <pose frame=''>0.16495 0 0.045 0 -0 0</pose>
      </sensor>
      <velocity_decay/>
      <sensor name='ir_left_front_sensor' type='ray'>
        <visualize>1</visualize>
        <update_rate>20</update_rate>
        <ray>
          <scan>
            <horizontal>
              <samples>10</samples>
              <resolution>1</resolution>
              <min_angle>-0.0872664</min_angle>
              <max_angle>0.0872664</max_angle>
            </horizontal>
          </scan>
          <range>
            <min>0.01</min>
            <max>0.26</max>
            <resolution>0.01</resolution>
          </range>
        </ray>
        <plugin name='gazebo_ros_ir_left_front_controller' filename='libgazebo_ros_range.so'>
          <gaussianNoise>0.005</gaussianNoise>
          <alwaysOn>true</alwaysOn>
          <updateRate>20</updateRate>
          <topicName>/ir/left_front</topicName>
          <frameName>base_link</frameName>
          <radiation>ir</radiation>
          <fov>0.174532777778</fov>
        </plugin>
        <pose frame=''>0.152394 0.063124 0.045 0 -0 0.392699</pose>
      </sensor>
      <velocity_decay/>
      <sensor name='ir_left_sensor' type='ray'>
        <visualize>1</visualize>
        <update_rate>20</update_rate>
        <ray>
          <scan>
            <horizontal>
              <samples>10</samples>
              <resolution>1</resolution>
              <min_angle>-0.0872664</min_angle>
              <max_angle>0.0872664</max_angle>
            </horizontal>
          </scan>
          <range>
            <min>0.01</min>
            <max>0.26</max>
            <resolution>0.01</resolution>
          </range>
        </ray>
        <plugin name='gazebo_ros_ir_left_controller' filename='libgazebo_ros_range.so'>
          <gaussianNoise>0.005</gaussianNoise>
          <alwaysOn>true</alwaysOn>
          <updateRate>20</updateRate>
          <topicName>/ir/left</topicName>
          <frameName>base_link</frameName>
          <radiation>ir</radiation>
          <fov>0.174532777778</fov>
        </plugin>
        <pose frame=''>0.116637 0.116637 0.045 0 -0 0.785397</pose>
      </sensor>
      <velocity_decay/>
      <velocity_decay/>
      <velocity_decay/>
      <velocity_decay/>
      <velocity_decay/>
      <sensor name='ir_right_front_sensor' type='ray'>
        <visualize>1</visualize>
        <update_rate>20</update_rate>
        <ray>
          <scan>
            <horizontal>
              <samples>10</samples>
              <resolution>1</resolution>
              <min_angle>-0.0872664</min_angle>
              <max_angle>0.0872664</max_angle>
            </horizontal>
          </scan>
          <range>
            <min>0.01</min>
            <max>0.26</max>
            <resolution>0.01</resolution>
          </range>
        </ray>
        <plugin name='gazebo_ros_ir_right_front_controller' filename='libgazebo_ros_range.so'>
          <gaussianNoise>0.005</gaussianNoise>
          <alwaysOn>true</alwaysOn>
          <updateRate>20</updateRate>
          <topicName>/ir/right_front</topicName>
          <frameName>base_link</frameName>
          <radiation>ir</radiation>
          <fov>0.174532777778</fov>
        </plugin>
        <pose frame=''>0.152394 -0.063124 0.045 0 0 -0.392699</pose>
      </sensor>
      <velocity_decay/>
      <sensor name='ir_right_sensor' type='ray'>
        <visualize>1</visualize>
        <update_rate>20</update_rate>
        <ray>
          <scan>
            <horizontal>
              <samples>10</samples>
              <resolution>1</resolution>
              <min_angle>-0.0872664</min_angle>
              <max_angle>0.0872664</max_angle>
            </horizontal>
          </scan>
          <range>
            <min>0.01</min>
            <max>0.26</max>
            <resolution>0.01</resolution>
          </range>
        </ray>
        <plugin name='gazebo_ros_ir_right_controller' filename='libgazebo_ros_range.so'>
          <gaussianNoise>0.005</gaussianNoise>
          <alwaysOn>true</alwaysOn>
          <updateRate>20</updateRate>
          <topicName>/ir/right</topicName>
          <frameName>base_link</frameName>
          <radiation>ir</radiation>
          <fov>0.174532777778</fov>
        </plugin>
        <pose frame=''>0.116637 -0.116637 0.045 0 0 -0.785397</pose>
      </sensor>
      <gravity>1</gravity>
      <velocity_decay/>
      <sensor name='eai_lidar' type='ray'>
        <visualize>0</visualize>
        <update_rate>5</update_rate>
        <ray>
          <scan>
            <horizontal>
              <samples>360</samples>
              <resolution>1</resolution>
              <min_angle>0</min_angle>
              <max_angle>6.28318</max_angle>
            </horizontal>
          </scan>
          <range>
            <min>0.1</min>
            <max>8</max>
            <resolution>0.01</resolution>
          </range>
          <noise>
            <type>gaussian</type>
            <mean>0</mean>
            <stddev>0.01</stddev>
          </noise>
        </ray>
        <plugin name='gazebo_ros_lidar_controller' filename='libgazebo_ros_laser.so'>
          <topicName>/laser/scan</topicName>
          <frameName>lidar_link</frameName>
        </plugin>
        <pose frame=''>0.045 0 0.085 0 -0 0</pose>
      </sensor>
    </link>
    <link name='left_wheel'>
      <pose frame=''>0 0.13 0.033 0 -0 0</pose>
      <inertial>
        <pose frame=''>0 0 0 0 -0 0</pose>
        <mass>0.2</mass>
        <inertia>
          <ixx>5.87167e-05</ixx>
          <ixy>0</ixy>
          <ixz>0</ixz>
          <iyy>5.87167e-05</iyy>
          <iyz>0</iyz>
          <izz>0.0001089</izz>
        </inertia>
      </inertial>
      <collision name='left_wheel_fixed_joint_lump__collision_collision'>
        <pose frame=''>0 0 0 0 1.5707 1.5707</pose>
        <geometry>
          <cylinder>
            <length>0.016</length>
            <radius>0.033</radius>
          </cylinder>
        </geometry>
      </collision>
      <visual name='left_wheel_visual'>
        <pose frame=''>0 0 0 0 1.5707 1.5707</pose>
        <geometry>
          <mesh>
            <scale>1 1 1</scale>
            <uri>model://sweeper_description/meshes/RobotWheel.dae</uri>
          </mesh>
        </geometry>
        <material>
          <script>
            <name>Gazebo/Black</name>
            <uri>file://media/materials/scripts/gazebo.material</uri>
          </script>
        </material>
      </visual>
      <gravity>1</gravity>
      <velocity_decay/>
    </link>
    <joint name='left_wheel_joint' type='revolute'>
      <child>left_wheel</child>
      <parent>base_link</parent>
      <axis>
        <xyz>0 1 0</xyz>
        <limit>
          <lower>-1e+16</lower>
          <upper>1e+16</upper>
        </limit>
        <dynamics>
          <spring_reference>0</spring_reference>
          <spring_stiffness>0</spring_stiffness>
        </dynamics>
        <use_parent_model_frame>1</use_parent_model_frame>
      </axis>
    </joint>
    <link name='right_wheel'>
      <pose frame=''>0 -0.13 0.033 0 -0 0</pose>
      <inertial>
        <pose frame=''>0 0 0 0 -0 0</pose>
        <mass>0.2</mass>
        <inertia>
          <ixx>5.87167e-05</ixx>
          <ixy>0</ixy>
          <ixz>0</ixz>
          <iyy>5.87167e-05</iyy>
          <iyz>0</iyz>
          <izz>0.0001089</izz>
        </inertia>
      </inertial>
      <collision name='right_wheel_fixed_joint_lump__collision_collision'>
        <pose frame=''>0 0 0 0 1.5707 1.5707</pose>
        <geometry>
          <cylinder>
            <length>0.016</length>
            <radius>0.033</radius>
          </cylinder>
        </geometry>
      </collision>
      <visual name='right_wheel_visual'>
        <pose frame=''>0 0 0 0 1.5707 1.5707</pose>
        <geometry>
          <mesh>
            <scale>1 1 1</scale>
            <uri>model://sweeper_description/meshes/RobotWheel.dae</uri>
          </mesh>
        </geometry>
        <material>
          <script>
            <name>Gazebo/Black</name>
            <uri>file://media/materials/scripts/gazebo.material</uri>
          </script>
        </material>
      </visual>
      <gravity>1</gravity>
      <velocity_decay/>
    </link>
    <joint name='right_wheel_joint' type='revolute'>
      <child>right_wheel</child>
      <parent>base_link</parent>
      <axis>
        <xyz>0 1 0</xyz>
        <limit>
          <lower>-1e+16</lower>
          <upper>1e+16</upper>
        </limit>
        <dynamics>
          <spring_reference>0</spring_reference>
          <spring_stiffness>0</spring_stiffness>
        </dynamics>
        <use_parent_model_frame>1</use_parent_model_frame>
      </axis>
    </joint>
    <static>0</static>
    <plugin name='gazebo_ros_control' filename='libgazebo_ros_control.so'>
      <robotNamespace>/</robotNamespace>
      <legacyModeNS>true</legacyModeNS>
    </plugin>
  </model>
</sdf>
