<sdf version='1.6'>
  <model name='rvc'>
    <link name='base_link'>
      <pose frame=''>0 0 0 0 -0 0</pose>
      <inertial>
        <pose frame=''>0.015 0 0.056667 0 -0 0</pose>
        <mass>0.6</mass>
        <inertia>
          <ixx>0.00309438</ixx>
          <ixy>0</ixy>
          <ixz>-0.00021</ixz>
          <iyy>0.00336438</iyy>
          <iyz>0</iyz>
          <izz>0.0057958</izz>
        </inertia>
      </inertial>
      <collision name='base_link_fixed_joint_lump__boby_collision_collision'>
        <pose frame=''>0 0 0.045 0 -0 0</pose>
        <geometry>
          <cylinder>
            <length>0.07</length>
            <radius>0.16495</radius>
          </cylinder>
        </geometry>
      </collision>
      <collision name='base_link_fixed_joint_lump__collision_collision_1'>
        <pose frame=''>0.045 0 0.08 0 -0 0</pose>
        <geometry>
          <cylinder>
            <length>0.017</length>
            <radius>0.029</radius>
          </cylinder>
        </geometry>
      </collision>
      <visual name='base_link_fixed_joint_lump__body_visual'>
        <pose frame=''>0 0 0.045 0 -0 0</pose>
        <geometry>
          <mesh>
            <scale>1 1 1</scale>
            <uri>model://sweeper_description/meshes/RobotBody.dae</uri>
          </mesh>
        </geometry>
      </visual>
      <visual name='base_link_fixed_joint_lump__imu_link_visual_1'>
        <pose frame=''>0 0 0.045 0 -0 0</pose>
        <geometry>
          <cylinder>
            <length>0.001</length>
            <radius>0.001</radius>
          </cylinder>
        </geometry>
        <material>
          <script>
            <uri>__default__</uri>
            <name>__default__</name>
          </script>
        </material>
      </visual>
      <visual name='base_link_fixed_joint_lump__ir_recevier_fl_visual_2'>
        <pose frame=''>0.161659 0.009711 0.06 0 -0 0.06</pose>
        <geometry>
          <sphere>
            <radius>0.005</radius>
          </sphere>
        </geometry>
        <material>
          <script>
            <name>Gazebo/Red</name>
            <uri>file://media/materials/scripts/gazebo.material</uri>
          </script>
        </material>
      </visual>
      <visual name='base_link_fixed_joint_lump__ir_recevier_fr_visual_3'>
        <pose frame=''>0.161659 -0.009711 0.06 0 0 -0.06</pose>
        <geometry>
          <sphere>
            <radius>0.005</radius>
          </sphere>
        </geometry>
        <material>
          <script>
            <name>Gazebo/Green</name>
            <uri>file://media/materials/scripts/gazebo.material</uri>
          </script>
        </material>
      </visual>
      <visual name='base_link_fixed_joint_lump__ir_recevier_l_visual_4'>
        <pose frame=''>0 0.16195 0.06 0 -0 1.57079</pose>
        <geometry>
          <sphere>
            <radius>0.005</radius>
          </sphere>
        </geometry>
        <material>
          <script>
            <name>Gazebo/Blue</name>
            <uri>file://media/materials/scripts/gazebo.material</uri>
          </script>
        </material>
      </visual>
      <visual name='base_link_fixed_joint_lump__ir_recevier_r_visual_5'>
        <pose frame=''>0 -0.16195 0.06 0 0 -1.57079</pose>
        <geometry>
          <sphere>
            <radius>0.005</radius>
          </sphere>
        </geometry>
        <material>
          <script>
            <name>Gazebo/Purple</name>
            <uri>file://media/materials/scripts/gazebo.material</uri>
          </script>
        </material>
      </visual>
      <visual name='base_link_fixed_joint_lump__laser_visual_visual_6'>
        <pose frame=''>0.045 0 0.08 0 -0 0</pose>
        <geometry>
          <mesh>
            <scale>1 1 1</scale>
            <uri>model://sweeper_description/meshes/RobotLidar.dae</uri>
          </mesh>
        </geometry>
      </visual>
      <velocity_decay/>
      <sensor name='main_bumper' type='contact'>
        <contact>
          <collision>base_link_fixed_joint_lump__boby_collision_collision</collision>
          <topic>__default_topic__</topic>
        </contact>
        <plugin name='gazebo_ros_bumper_controller' filename='libgazebo_ros_bumper.so'>
          <selfCollide>true</selfCollide>
          <alwaysOn>true</alwaysOn>
          <updateRate>20.0</updateRate>
          <bumperTopicName>/bumper</bumperTopicName>
          <frameName>base_link</frameName>
        </plugin>
      </sensor>
      <velocity_decay/>
      <sensor name='imu_sensor' type='imu'>
        <always_on>1</always_on>
        <update_rate>100</update_rate>
        <visualize>1</visualize>
        <topic>__default_topic__</topic>
        <plugin name='imu_plugin' filename='libgazebo_ros_imu_sensor.so'>
          <topicName>/imu</topicName>
          <bodyName>imu_link</bodyName>
          <updateRateHZ>50.0</updateRateHZ>
          <gaussianNoise>0.0</gaussianNoise>
          <xyzOffset>0 0 0</xyzOffset>
          <rpyOffset>0 0 0</rpyOffset>
          <frameName>imu_link</frameName>
          <initialOrientationAsReference>false</initialOrientationAsReference>
        </plugin>
        <pose frame=''>0 0 0.045 0 -0 0</pose>
      </sensor>
      <velocity_decay/>
      <sensor name='ir_front_sensor' type='ray'>
        <visualize>1</visualize>
        <update_rate>20</update_rate>
        <ray>
          <scan>
            <horizontal>
              <samples>10</samples>
              <resolution>1</resolution>
              <min_angle>-0.0872664</min_angle>
              <max_angle>0.0872664</max_angle>
            </horizontal>
          </scan>
          <range>
            <min>0.01</min>
            <max>0.26</max>
            <resolution>0.01</resolution>
          </range>
        </ray>
        <plugin name='gazebo_ros_ir_front_controller' filename='libgazebo_ros_range.so'>
          <gaussianNoise>0.005</gaussianNoise>
          <alwaysOn>true</alwaysOn>
          <updateRate>20</updateRate>
          <topicName>/ir/front</topicName>
          <frameName>base_link</frameName>
          <radiation>ir</radiation>
          <fov>0.174532777778</fov>
        </plugin>
        <pose frame=''>0.16495 0 0.045 0 -0 0</pose>
      </sensor>
      <velocity_decay/>
      <sensor name='ir_left_front_sensor' type='ray'>
        <visualize>1</visualize>
        <update_rate>20</update_rate>
        <ray>
          <scan>
            <horizontal>
              <samples>10</samples>
              <resolution>1</resolution>
              <min_angle>-0.0872664</min_angle>
              <max_angle>0.0872664</max_angle>
            </horizontal>
          </scan>
          <range>
            <min>0.01</min>
            <max>0.26</max>
            <resolution>0.01</resolution>
          </range>
        </ray>
        <plugin name='gazebo_ros_ir_left_front_controller' filename='libgazebo_ros_range.so'>
          <gaussianNoise>0.005</gaussianNoise>
          <alwaysOn>true</alwaysOn>
          <updateRate>20</updateRate>
          <topicName>/ir/left_front</topicName>
          <frameName>base_link</frameName>
          <radiation>ir</radiation>
          <fov>0.174532777778</fov>
        </plugin>
        <pose frame=''>0.116637 0.116637 0.045 0 -0 0.785397</pose>
      </sensor>
      <velocity_decay/>
      <sensor name='ir_left_sensor' type='ray'>
        <visualize>1</visualize>
        <update_rate>20</update_rate>
        <ray>
          <scan>
            <horizontal>
              <samples>10</samples>
              <resolution>1</resolution>
              <min_angle>-0.0872664</min_angle>
              <max_angle>0.0872664</max_angle>
            </horizontal>
          </scan>
          <range>
            <min>0.01</min>
            <max>0.26</max>
            <resolution>0.01</resolution>
          </range>
        </ray>
        <plugin name='gazebo_ros_ir_left_controller' filename='libgazebo_ros_range.so'>
          <gaussianNoise>0.005</gaussianNoise>
          <alwaysOn>true</alwaysOn>
          <updateRate>20</updateRate>
          <topicName>/ir/left</topicName>
          <frameName>base_link</frameName>
          <radiation>ir</radiation>
          <fov>0.174532777778</fov>
        </plugin>
        <pose frame=''>0 0.16495 0.045 0 -0 1.57079</pose>
      </sensor>
      <velocity_decay/>
      <velocity_decay/>
      <velocity_decay/>
      <velocity_decay/>
      <velocity_decay/>
      <sensor name='ir_right_front_sensor' type='ray'>
        <visualize>1</visualize>
        <update_rate>20</update_rate>
        <ray>
          <scan>
            <horizontal>
              <samples>10</samples>
              <resolution>1</resolution>
              <min_angle>-0.0872664</min_angle>
              <max_angle>0.0872664</max_angle>
            </horizontal>
          </scan>
          <range>
            <min>0.01</min>
            <max>0.26</max>
            <resolution>0.01</resolution>
          </range>
        </ray>
        <plugin name='gazebo_ros_ir_right_front_controller' filename='libgazebo_ros_range.so'>
          <gaussianNoise>0.005</gaussianNoise>
          <alwaysOn>true</alwaysOn>
          <updateRate>20</updateRate>
          <topicName>/ir/right_front</topicName>
          <frameName>base_link</frameName>
          <radiation>ir</radiation>
          <fov>0.174532777778</fov>
        </plugin>
        <pose frame=''>0.116637 -0.116637 0.045 0 0 -0.785397</pose>
      </sensor>
      <gravity>1</gravity>
      <velocity_decay/>
      <sensor name='ir_right_sensor' type='ray'>
        <visualize>1</visualize>
        <update_rate>20</update_rate>
        <ray>
          <scan>
            <horizontal>
              <samples>10</samples>
              <resolution>1</resolution>
              <min_angle>-0.0872664</min_angle>
              <max_angle>0.0872664</max_angle>
            </horizontal>
          </scan>
          <range>
            <min>0.01</min>
            <max>0.26</max>
            <resolution>0.01</resolution>
          </range>
        </ray>
        <plugin name='gazebo_ros_ir_right_controller' filename='libgazebo_ros_range.so'>
          <gaussianNoise>0.005</gaussianNoise>
          <alwaysOn>true</alwaysOn>
          <updateRate>20</updateRate>
          <topicName>/ir/right</topicName>
          <frameName>base_link</frameName>
          <radiation>ir</radiation>
          <fov>0.174532777778</fov>
        </plugin>
        <pose frame=''>0 -0.16495 0.045 0 0 -1.57079</pose>
      </sensor>
      <gravity>1</gravity>
      <velocity_decay/>
      <sensor name='eai_lidar' type='ray'>
        <visualize>0</visualize>
        <update_rate>5</update_rate>
        <ray>
          <scan>
            <horizontal>
              <samples>360</samples>
              <resolution>1</resolution>
              <min_angle>0</min_angle>
              <max_angle>6.28318</max_angle>
            </horizontal>
          </scan>
          <range>
            <min>0.1</min>
            <max>8</max>
            <resolution>0.01</resolution>
          </range>
          <noise>
            <type>gaussian</type>
            <mean>0</mean>
            <stddev>0.01</stddev>
          </noise>
        </ray>
        <plugin name='gazebo_ros_lidar_controller' filename='libgazebo_ros_laser.so'>
          <topicName>/scan</topicName>
          <frameName>lidar_link</frameName>
        </plugin>
        <pose frame=''>0.045 0 0.085 0 -0 0</pose>
      </sensor>
    </link>
    <link name='front_omni'>
      <pose frame=''>0.11 0 -0.035 0 -0 0</pose>
      <inertial>
        <pose frame=''>0 0 0 0 -0 0</pose>
        <mass>0.1</mass>
        <inertia>
          <ixx>4e-06</ixx>
          <ixy>0</ixy>
          <ixz>0</ixz>
          <iyy>4e-06</iyy>
          <iyz>0</iyz>
          <izz>4e-06</izz>
        </inertia>
      </inertial>
      <collision name='front_omniwheel_collision'>
        <pose frame=''>0 0 0 0 -0 0</pose>
        <geometry>
          <sphere>
            <radius>0.01</radius>
          </sphere>
        </geometry>
        <surface>
          <contact>
            <ode>
              <kp>1e+07</kp>
              <kd>10</kd>
              <max_vel>1</max_vel>
              <min_depth>0</min_depth>
            </ode>
          </contact>
          <friction>
            <ode>
              <mu>0</mu>
              <mu2>0</mu2>
              <fdir1>1 0 0</fdir1>
            </ode>
          </friction>
        </surface>
      </collision>
      <visual name='front_omni_visual'>
        <pose frame=''>0 0 0 0 -0 0</pose>
        <geometry>
          <sphere>
            <radius>0.01</radius>
          </sphere>
        </geometry>
        <material>
          <script>
            <name>Gazebo/Black</name>
            <uri>file://media/materials/scripts/gazebo.material</uri>
          </script>
        </material>
      </visual>
      <gravity>1</gravity>
      <velocity_decay/>
    </link>
    <joint name='front_omni_to_base' type='revolute'>
      <child>front_omni</child>
      <parent>base_link</parent>
      <axis>
        <xyz>0 1 0</xyz>
        <limit>
          <lower>-1e+16</lower>
          <upper>1e+16</upper>
        </limit>
        <dynamics>
          <spring_reference>0</spring_reference>
          <spring_stiffness>0</spring_stiffness>
        </dynamics>
        <use_parent_model_frame>1</use_parent_model_frame>
      </axis>
    </joint>
    <link name='left_wheel'>
      <pose frame=''>0 0.13 -0.012 0 -0 0</pose>
      <inertial>
        <pose frame=''>0 0 0 0 -0 0</pose>
        <mass>0.2</mass>
        <inertia>
          <ixx>5.87167e-05</ixx>
          <ixy>0</ixy>
          <ixz>0</ixz>
          <iyy>5.87167e-05</iyy>
          <iyz>0</iyz>
          <izz>0.0001089</izz>
        </inertia>
      </inertial>
      <collision name='left_wheel_collision_collision'>
        <pose frame=''>0 0 0 0 1.5707 1.5707</pose>
        <geometry>
          <cylinder>
            <length>0.016</length>
            <radius>0.033</radius>
          </cylinder>
        </geometry>
        <surface>
          <contact>
            <ode>
              <kp>1e+07</kp>
              <kd>10</kd>
              <max_vel>1</max_vel>
              <min_depth>0</min_depth>
            </ode>
          </contact>
          <friction>
            <ode>
              <mu>200</mu>
              <mu2>100</mu2>
              <fdir1>1 0 0</fdir1>
            </ode>
          </friction>
        </surface>
      </collision>
      <visual name='left_wheel_visual'>
        <pose frame=''>0 0 0 0 1.5707 1.5707</pose>
        <geometry>
          <mesh>
            <scale>1 1 1</scale>
            <uri>model://sweeper_description/meshes/RobotWheel.dae</uri>
          </mesh>
        </geometry>
        <material>
          <script>
            <name>Gazebo/Black</name>
            <uri>file://media/materials/scripts/gazebo.material</uri>
          </script>
        </material>
      </visual>
      <gravity>1</gravity>
      <velocity_decay/>
    </link>
    <joint name='left_wheel_joint' type='revolute'>
      <child>left_wheel</child>
      <parent>base_link</parent>
      <axis>
        <xyz>0 1 0</xyz>
        <limit>
          <lower>-1e+16</lower>
          <upper>1e+16</upper>
        </limit>
        <dynamics>
          <spring_reference>0</spring_reference>
          <spring_stiffness>0</spring_stiffness>
        </dynamics>
        <use_parent_model_frame>1</use_parent_model_frame>
      </axis>
    </joint>
    <link name='right_wheel'>
      <pose frame=''>0 -0.13 -0.012 0 -0 0</pose>
      <inertial>
        <pose frame=''>0 0 0 0 -0 0</pose>
        <mass>0.2</mass>
        <inertia>
          <ixx>5.87167e-05</ixx>
          <ixy>0</ixy>
          <ixz>0</ixz>
          <iyy>5.87167e-05</iyy>
          <iyz>0</iyz>
          <izz>0.0001089</izz>
        </inertia>
      </inertial>
      <collision name='right_wheel_collision_collision'>
        <pose frame=''>0 0 0 0 1.5707 1.5707</pose>
        <geometry>
          <cylinder>
            <length>0.016</length>
            <radius>0.033</radius>
          </cylinder>
        </geometry>
        <surface>
          <contact>
            <ode>
              <kp>1e+07</kp>
              <kd>10</kd>
              <max_vel>1</max_vel>
              <min_depth>0</min_depth>
            </ode>
          </contact>
          <friction>
            <ode>
              <mu>200</mu>
              <mu2>100</mu2>
              <fdir1>1 0 0</fdir1>
            </ode>
          </friction>
        </surface>
      </collision>
      <visual name='right_wheel_visual'>
        <pose frame=''>0 0 0 0 1.5707 1.5707</pose>
        <geometry>
          <mesh>
            <scale>1 1 1</scale>
            <uri>model://sweeper_description/meshes/RobotWheel.dae</uri>
          </mesh>
        </geometry>
        <material>
          <script>
            <name>Gazebo/Black</name>
            <uri>file://media/materials/scripts/gazebo.material</uri>
          </script>
        </material>
      </visual>
      <gravity>1</gravity>
      <velocity_decay/>
    </link>
    <joint name='right_wheel_joint' type='revolute'>
      <child>right_wheel</child>
      <parent>base_link</parent>
      <axis>
        <xyz>0 1 0</xyz>
        <limit>
          <lower>-1e+16</lower>
          <upper>1e+16</upper>
        </limit>
        <dynamics>
          <spring_reference>0</spring_reference>
          <spring_stiffness>0</spring_stiffness>
        </dynamics>
        <use_parent_model_frame>1</use_parent_model_frame>
      </axis>
    </joint>
    <static>0</static>
    <plugin name='gazebo_ros_control' filename='libgazebo_ros_control.so'>
      <robotNamespace>/</robotNamespace>
      <legacyModeNS>true</legacyModeNS>
    </plugin>
  </model>
</sdf>
