<?xml version="1.0" ?>
<!-- =================================================================================== -->
<!-- |    This document was autogenerated by xacro from bl5xx.xacro                    | -->
<!-- |    EDITING THIS FILE BY HAND IS NOT RECOMMENDED                                 | -->
<!-- =================================================================================== -->
<robot name="rvc" xmlns:controller="http://playerstage.sourceforge.net/gazebo/xmlschema/#controller" xmlns:interface="http://playerstage.sourceforge.net/gazebo/xmlschema/#interface" xmlns:sensor="http://playerstage.sourceforge.net/gazebo/xmlschema/#sensor" xmlns:xacro="http://ros.org/wiki/xacro">
  <link name="base_link"/>
  <link name="body">
    <visual>
      <origin rpy="0 0 0" xyz="0 0 0"/>
      <geometry>
        <mesh filename="package://sweeper_description/meshes/RobotBody.dae"/>
      </geometry>
      <material name="white"/>
    </visual>
    <collision name="boby_collision">
      <origin rpy="0 0 0" xyz="0 0 0"/>
      <geometry>
        <cylinder length="0.07" radius="0.16495"/>
      </geometry>
    </collision>
    <inertial>
      <origin rpy="0 0 0" xyz="0 0 0"/>
      <mass value="0.4"/>
      <inertia ixx="0.00288418358333" ixy="0.0" ixz="0.0" iyy="0.00288418358333" iyz="0.0" izz="0.0054417005"/>
    </inertial>
  </link>
  <joint name="body_to_base" type="fixed">
    <axis rpy="0 0 0" xyz="0 0 0"/>
    <parent link="base_link"/>
    <child link="body"/>
    <origin rpy="0 0 0" xyz="0 0 0.045"/>
  </joint>
  <gazebo reference="base_link">
    <sensor name="main_bumper" type="contact">
      <contact>
        <collision>base_link_fixed_joint_lump__boby_collision_collision</collision>
      </contact>
      <plugin filename="libgazebo_ros_bumper.so" name="gazebo_ros_bumper_controller">
        <selfCollide>true</selfCollide>
        <alwaysOn>true</alwaysOn>
        <updateRate>20.0</updateRate>
        <bumperTopicName>/bumper</bumperTopicName>
        <frameName>base_link</frameName>
      </plugin>
    </sensor>
    <material>Gazebo/White</material>
  </gazebo>
  <link name="front_omni">
    <inertial>
      <mass value="0.1"/>
      <inertia ixx="4e-06" ixy="0" ixz="0" iyy="4e-06" iyz="0" izz="4e-06"/>
    </inertial>
    <visual>
      <origin rpy="0 0 0" xyz="0 0 0"/>
      <geometry>
        <sphere radius="0.01"/>
      </geometry>
    </visual>
    <collision name="front_omniwheel">
      <origin rpy="0 0 0" xyz="0 0 0"/>
      <geometry>
        <sphere radius="0.01"/>
      </geometry>
    </collision>
  </link>
  <joint name="front_omni_to_base" type="continuous">
    <parent link="base_link"/>
    <child link="front_omni"/>
    <origin rpy="0 0 0" xyz="0.11 0 -0.035"/>
    <axis xyz="0 1 0"/>
  </joint>
  <gazebo reference="front_omni">
    <mu1>0.0</mu1>
    <mu2>0.0</mu2>
    <kp>10000000.0</kp>
    <kd>10.0</kd>
    <fdir1>1 0 0</fdir1>
    <maxVel>1.0</maxVel>
    <minDepth>0.00</minDepth>
    <turnGravityOff>false</turnGravityOff>
    <material>Gazebo/Black</material>
  </gazebo>
  <!-- <link name="back_omni">
    <inertial>
      <origin xyz="0 0 0" rpy="0 0 0"/>
      <mass value="0.1"/>
      <inertia ixx="0.001" ixy="0.001" ixz="0.001" iyy="0.001" iyz="0.001" izz="0.001"/>
    </inertial>
    <visual>
      <origin xyz="0 0 0" rpy="0 0 0" />
      <geometry>
        <sphere radius="${body_to_ground}"/>
      </geometry>
    </visual>
    <collision name="back_omniwheel">
      <origin xyz="0 0 0" rpy="0 0 0" />
      <geometry>
        <sphere radius="${body_to_ground}"/>
      </geometry>
    </collision>
  </link>
  <joint name="back_omni_to_base" type="fixed">
    <parent link="base_link"/>
    <child link="back_omni"/>
    <origin xyz="-0.11 0 -${body_to_ground+body_height/2-body_to_ground}" rpy="0 0 0"/>
  </joint> -->
  <link name="left_wheel">
    <collision name="left_wheel_collision">
      <origin rpy="0 1.570700 1.570700" xyz="0 0 0"/>
      <geometry>
        <cylinder length="0.016" radius="0.033"/>
      </geometry>
      <surface>
        <friction>
          <ode>
            <mu>1</mu>
            <mu2>0</mu2>
            <fdir1>0 1.0 0</fdir1>
            <implicit_spring_damper>true</implicit_spring_damper>
          </ode>
        </friction>
      </surface>
    </collision>
    <visual>
      <origin rpy="0 1.570700 1.570700" xyz="0 0 0"/>
      <geometry>
        <mesh filename="package://sweeper_description/meshes/RobotWheel.dae"/>
      </geometry>
    </visual>
    <inertial>
      <origin rpy="0 0 0" xyz="0 0 0"/>
      <mass value="0.2"/>
      <inertia ixx="5.87166666667e-05" ixy="0.0" ixz="0.0" iyy="5.87166666667e-05" iyz="0.0" izz="0.0001089"/>
    </inertial>
  </link>
  <joint name="left_wheel_joint" type="continuous">
    <parent link="base_link"/>
    <child link="left_wheel"/>
    <axis rpy="0 0 0" xyz="0 1 0"/>
    <origin rpy="0 0 0" xyz="0 0.13 -0.012"/>
  </joint>
  <transmission name="left_wheel_trans">
    <type>transmission_interface/SimpleTransmission</type>
    <actuator name="left_wheel_motor">
      <mechanicalReduction>1</mechanicalReduction>
    </actuator>
    <joint name="left_wheel_joint">
      <hardwareInterface>hardware_interface/VelocityJointInterface</hardwareInterface>
    </joint>
  </transmission>
  <gazebo reference="left_wheel">
    <mu1>200.0</mu1>
    <mu2>100.0</mu2>
    <kp>10000000.0</kp>
    <kd>10.0</kd>
    <fdir1>1 0 0</fdir1>
    <maxVel>1.0</maxVel>
    <minDepth>0.00</minDepth>
    <material>Gazebo/Black</material>
  </gazebo>
  <link name="right_wheel">
    <collision name="right_wheel_collision">
      <origin rpy="0 1.570700 1.570700" xyz="0 0 0"/>
      <geometry>
        <cylinder length="0.016" radius="0.033"/>
      </geometry>
      <surface>
        <friction>
          <ode>
            <mu>1</mu>
            <mu2>0</mu2>
            <fdir1>0 1.0 0</fdir1>
            <implicit_spring_damper>true</implicit_spring_damper>
          </ode>
        </friction>
      </surface>
    </collision>
    <visual>
      <origin rpy="0 1.570700 1.570700" xyz="0 0 0"/>
      <geometry>
        <mesh filename="package://sweeper_description/meshes/RobotWheel.dae"/>
      </geometry>
    </visual>
    <inertial>
      <origin rpy="0 0 0" xyz="0 0 0"/>
      <mass value="0.2"/>
      <inertia ixx="5.87166666667e-05" ixy="0.0" ixz="0.0" iyy="5.87166666667e-05" iyz="0.0" izz="0.0001089"/>
    </inertial>
  </link>
  <joint name="right_wheel_joint" type="continuous">
    <parent link="base_link"/>
    <child link="right_wheel"/>
    <axis rpy="0 0 0" xyz="0 1 0"/>
    <origin rpy="0 0 0" xyz="0 -0.13 -0.012"/>
  </joint>
  <transmission name="right_wheel_trans">
    <type>transmission_interface/SimpleTransmission</type>
    <actuator name="right_wheel_motor">
      <mechanicalReduction>1</mechanicalReduction>
    </actuator>
    <joint name="right_wheel_joint">
      <hardwareInterface>hardware_interface/VelocityJointInterface</hardwareInterface>
    </joint>
  </transmission>
  <gazebo reference="right_wheel">
    <mu1>200.0</mu1>
    <mu2>100.0</mu2>
    <kp>10000000.0</kp>
    <kd>10.0</kd>
    <fdir1>1 0 0</fdir1>
    <maxVel>1.0</maxVel>
    <minDepth>0.00</minDepth>
    <material>Gazebo/Black</material>
  </gazebo>
  <link name="ir_left"/>
  <joint name="ir_left_joint" type="fixed">
    <axis rpy="0 0 0" xyz="0 0 0"/>
    <parent link="body"/>
    <child link="ir_left"/>
    <origin rpy="0 0 1.570795" xyz="2.18854818207e-07 0.16495 0"/>
  </joint>
  <gazebo reference="ir_left">
    <sensor name="ir_left_sensor" type="ray">
      <pose>0 0 0 0 0 0</pose>
      <visualize>true</visualize>
      <update_rate>20</update_rate>
      <ray>
        <scan>
          <horizontal>
            <samples>10</samples>
            <resolution>1</resolution>
            <min_angle>-0.0872663888889</min_angle>
            <max_angle>0.0872663888889</max_angle>
          </horizontal>
        </scan>
        <range>
          <min>0.01</min>
          <max>0.26</max>
          <resolution>0.01</resolution>
        </range>
      </ray>
      <plugin filename="libgazebo_ros_range.so" name="gazebo_ros_ir_left_controller">
        <gaussianNoise>0.005</gaussianNoise>
        <alwaysOn>true</alwaysOn>
        <updateRate>20</updateRate>
        <topicName>/ir/left</topicName>
        <frameName>base_link</frameName>
        <radiation>ir</radiation>
        <fov>0.174532777778</fov>
      </plugin>
    </sensor>
  </gazebo>
  <link name="ir_left_front"/>
  <joint name="ir_left_front_joint" type="fixed">
    <axis rpy="0 0 0" xyz="0 0 0"/>
    <parent link="body"/>
    <child link="ir_left_front"/>
    <origin rpy="0 0 0.7853975" xyz="0.116637340934 0.11663718618 0"/>
  </joint>
  <gazebo reference="ir_left_front">
    <sensor name="ir_left_front_sensor" type="ray">
      <pose>0 0 0 0 0 0</pose>
      <visualize>true</visualize>
      <update_rate>20</update_rate>
      <ray>
        <scan>
          <horizontal>
            <samples>10</samples>
            <resolution>1</resolution>
            <min_angle>-0.0872663888889</min_angle>
            <max_angle>0.0872663888889</max_angle>
          </horizontal>
        </scan>
        <range>
          <min>0.01</min>
          <max>0.26</max>
          <resolution>0.01</resolution>
        </range>
      </ray>
      <plugin filename="libgazebo_ros_range.so" name="gazebo_ros_ir_left_front_controller">
        <gaussianNoise>0.005</gaussianNoise>
        <alwaysOn>true</alwaysOn>
        <updateRate>20</updateRate>
        <topicName>/ir/left_front</topicName>
        <frameName>base_link</frameName>
        <radiation>ir</radiation>
        <fov>0.174532777778</fov>
      </plugin>
    </sensor>
  </gazebo>
  <link name="ir_front"/>
  <joint name="ir_front_joint" type="fixed">
    <axis rpy="0 0 0" xyz="0 0 0"/>
    <parent link="body"/>
    <child link="ir_front"/>
    <origin rpy="0 0 0" xyz="0.16495 0.0 0"/>
  </joint>
  <gazebo reference="ir_front">
    <sensor name="ir_front_sensor" type="ray">
      <pose>0 0 0 0 0 0</pose>
      <visualize>true</visualize>
      <update_rate>20</update_rate>
      <ray>
        <scan>
          <horizontal>
            <samples>10</samples>
            <resolution>1</resolution>
            <min_angle>-0.0872663888889</min_angle>
            <max_angle>0.0872663888889</max_angle>
          </horizontal>
        </scan>
        <range>
          <min>0.01</min>
          <max>0.26</max>
          <resolution>0.01</resolution>
        </range>
      </ray>
      <plugin filename="libgazebo_ros_range.so" name="gazebo_ros_ir_front_controller">
        <gaussianNoise>0.005</gaussianNoise>
        <alwaysOn>true</alwaysOn>
        <updateRate>20</updateRate>
        <topicName>/ir/front</topicName>
        <frameName>base_link</frameName>
        <radiation>ir</radiation>
        <fov>0.174532777778</fov>
      </plugin>
    </sensor>
  </gazebo>
  <link name="ir_right_front"/>
  <joint name="ir_right_front_joint" type="fixed">
    <axis rpy="0 0 0" xyz="0 0 0"/>
    <parent link="body"/>
    <child link="ir_right_front"/>
    <origin rpy="0 0 -0.7853975" xyz="0.116637340934 -0.11663718618 0"/>
  </joint>
  <gazebo reference="ir_right_front">
    <sensor name="ir_right_front_sensor" type="ray">
      <pose>0 0 0 0 0 0</pose>
      <visualize>true</visualize>
      <update_rate>20</update_rate>
      <ray>
        <scan>
          <horizontal>
            <samples>10</samples>
            <resolution>1</resolution>
            <min_angle>-0.0872663888889</min_angle>
            <max_angle>0.0872663888889</max_angle>
          </horizontal>
        </scan>
        <range>
          <min>0.01</min>
          <max>0.26</max>
          <resolution>0.01</resolution>
        </range>
      </ray>
      <plugin filename="libgazebo_ros_range.so" name="gazebo_ros_ir_right_front_controller">
        <gaussianNoise>0.005</gaussianNoise>
        <alwaysOn>true</alwaysOn>
        <updateRate>20</updateRate>
        <topicName>/ir/right_front</topicName>
        <frameName>base_link</frameName>
        <radiation>ir</radiation>
        <fov>0.174532777778</fov>
      </plugin>
    </sensor>
  </gazebo>
  <link name="ir_right"/>
  <joint name="ir_right_joint" type="fixed">
    <axis rpy="0 0 0" xyz="0 0 0"/>
    <parent link="body"/>
    <child link="ir_right"/>
    <origin rpy="0 0 -1.570795" xyz="2.18854818207e-07 -0.16495 0"/>
  </joint>
  <gazebo reference="ir_right">
    <sensor name="ir_right_sensor" type="ray">
      <pose>0 0 0 0 0 0</pose>
      <visualize>true</visualize>
      <update_rate>20</update_rate>
      <ray>
        <scan>
          <horizontal>
            <samples>10</samples>
            <resolution>1</resolution>
            <min_angle>-0.0872663888889</min_angle>
            <max_angle>0.0872663888889</max_angle>
          </horizontal>
        </scan>
        <range>
          <min>0.01</min>
          <max>0.26</max>
          <resolution>0.01</resolution>
        </range>
      </ray>
      <plugin filename="libgazebo_ros_range.so" name="gazebo_ros_ir_right_controller">
        <gaussianNoise>0.005</gaussianNoise>
        <alwaysOn>true</alwaysOn>
        <updateRate>20</updateRate>
        <topicName>/ir/right</topicName>
        <frameName>base_link</frameName>
        <radiation>ir</radiation>
        <fov>0.174532777778</fov>
      </plugin>
    </sensor>
  </gazebo>
  <link name="ir_recevier_fl">
    <visual>
      <origin rpy="0 0 0" xyz="0 0 0"/>
      <geometry>
        <sphere radius="0.005"/>
      </geometry>
    </visual>
  </link>
  <joint name="ir_recevier_fl_joint" type="fixed">
    <axis rpy="0 0 0" xyz="0 0 0"/>
    <parent link="body"/>
    <child link="ir_recevier_fl"/>
    <origin rpy="0 0 0.06" xyz="0.161658577443 0.00971117084935 0.015"/>
  </joint>
  <gazebo reference="ir_recevier_fl">
    <material>Gazebo/Red</material>
  </gazebo>
  <link name="ir_recevier_fr">
    <visual>
      <origin rpy="0 0 0" xyz="0 0 0"/>
      <geometry>
        <sphere radius="0.005"/>
      </geometry>
    </visual>
  </link>
  <joint name="ir_recevier_fr_joint" type="fixed">
    <axis rpy="0 0 0" xyz="0 0 0"/>
    <parent link="body"/>
    <child link="ir_recevier_fr"/>
    <origin rpy="0 0 -0.06" xyz="0.161658577443 -0.00971117084935 0.015"/>
  </joint>
  <gazebo reference="ir_recevier_fr">
    <material>Gazebo/Green</material>
  </gazebo>
  <link name="ir_recevier_l">
    <visual>
      <origin rpy="0 0 0" xyz="0 0 0"/>
      <geometry>
        <sphere radius="0.005"/>
      </geometry>
    </visual>
  </link>
  <joint name="ir_recevier_l_joint" type="fixed">
    <axis rpy="0 0 0" xyz="0 0 0"/>
    <parent link="body"/>
    <child link="ir_recevier_l"/>
    <origin rpy="0 0 1.570795" xyz="2.14874433517e-07 0.16195 0.015"/>
  </joint>
  <gazebo reference="ir_recevier_l">
    <material>Gazebo/Blue</material>
  </gazebo>
  <link name="ir_recevier_r">
    <visual>
      <origin rpy="0 0 0" xyz="0 0 0"/>
      <geometry>
        <sphere radius="0.005"/>
      </geometry>
    </visual>
  </link>
  <joint name="ir_recevier_r_joint" type="fixed">
    <axis rpy="0 0 0" xyz="0 0 0"/>
    <parent link="body"/>
    <child link="ir_recevier_r"/>
    <origin rpy="0 0 -1.570795" xyz="2.14874433517e-07 -0.16195 0.015"/>
  </joint>
  <gazebo reference="ir_recevier_r">
    <material>Gazebo/Purple</material>
  </gazebo>
  <link name="lidar_link">
    <collision name="collision">
      <origin rpy="0 0 0" xyz="0 0 0"/>
      <geometry>
        <cylinder length="0.017" radius="0.029"/>
      </geometry>
    </collision>
    <visual name="laser_visual">
      <origin rpy="0 0 0" xyz="0 0 0"/>
      <geometry>
        <mesh filename="package://sweeper_description/meshes/RobotLidar.dae"/>
      </geometry>
    </visual>
    <inertial>
      <mass value="0.2"/>
      <inertia ixx="4.68666666667e-05" ixy="0.0" ixz="0.0" iyy="4.68666666667e-05" iyz="0.0" izz="8.41e-05"/>
    </inertial>
  </link>
  <link name="laser_link">
    </link>
  <joint name="laser_joint" type="fixed">
    <axis rpy="0 0 0" xyz="0 0 0"/>
    <parent link="lidar_link"/>
    <child link="laser_link"/>
    <origin rpy="0 0 0" xyz="0 0 0.005"/>
  </joint>
  <gazebo reference="laser_link">
    <sensor name="eai_lidar" type="ray">
      <pose>0 0 0 0 0 0</pose>
      <visualize>false</visualize>
      <update_rate>5</update_rate>
      <ray>
        <scan>
          <horizontal>
            <samples>360</samples>
            <resolution>1</resolution>
            <min_angle>0</min_angle>
            <max_angle>6.28318</max_angle>
          </horizontal>
        </scan>
        <range>
          <min>0.10</min>
          <max>8.0</max>
          <resolution>0.01</resolution>
        </range>
        <noise>
          <type>gaussian</type>
          <!-- Noise parameters based on published spec for Hokuyo laser
               achieving "+-30mm" accuracy at range < 10m.  A mean of 0.0m and
               stddev of 0.01m will put 99.7% of samples within 0.03m of the true
               reading. -->
          <mean>0.0</mean>
          <stddev>0.01</stddev>
        </noise>
      </ray>
      <plugin filename="libgazebo_ros_laser.so" name="gazebo_ros_lidar_controller">
        <topicName>/scan</topicName>
        <frameName>lidar_link</frameName>
      </plugin>
    </sensor>
  </gazebo>
  <joint name="lidar_joint" type="fixed">
    <parent link="body"/>
    <child link="lidar_link"/>
    <origin xyz="0.045 0 0.035"/>
  </joint>
  <!--xacro:include filename="imu.xacro" /-->
  <link name="imu_link">
    <visual>
      <origin rpy="0 0 0" xyz="0 0 0"/>
      <geometry>
        <cylinder length="0.001" radius="0.001"/>
      </geometry>
      <material name="white"/>
    </visual>
  </link>
  <joint name="imu_joint" type="fixed">
    <parent link="body"/>
    <child link="imu_link"/>
    <origin xyz="0 0 0"/>
  </joint>
  <gazebo reference="imu_link">
    <gravity>true</gravity>
    <sensor name="imu_sensor" type="imu">
      <always_on>true</always_on>
      <update_rate>100</update_rate>
      <visualize>true</visualize>
      <topic>__default_topic__</topic>
      <plugin filename="libgazebo_ros_imu_sensor.so" name="imu_plugin">
        <topicName>/imu</topicName>
        <bodyName>imu_link</bodyName>
        <updateRateHZ>50.0</updateRateHZ>
        <gaussianNoise>0.0</gaussianNoise>
        <xyzOffset>0 0 0</xyzOffset>
        <rpyOffset>0 0 0</rpyOffset>
        <frameName>imu_link</frameName>
        <initialOrientationAsReference>false</initialOrientationAsReference>
      </plugin>
      <pose>0 0 0 0 0 0</pose>
    </sensor>
  </gazebo>
  <!-- Gazebo plugin for ROS Control -->
  <gazebo>
    <plugin filename="libgazebo_ros_control.so" name="gazebo_ros_control">
      <robotNamespace>/</robotNamespace>
      <legacyModeNS>true</legacyModeNS>
    </plugin>
  </gazebo>
</robot>

